[2023-04-05T03:00:00.646+0000] {taskinstance.py:1090} INFO - Dependencies all met for dep_context=non-requeueable deps ti=<TaskInstance: ELT.create_extract_data manual__2023-04-05T02:59:59.531240+00:00 [queued]>
[2023-04-05T03:00:00.654+0000] {taskinstance.py:1090} INFO - Dependencies all met for dep_context=requeueable deps ti=<TaskInstance: ELT.create_extract_data manual__2023-04-05T02:59:59.531240+00:00 [queued]>
[2023-04-05T03:00:00.654+0000] {taskinstance.py:1288} INFO - 
--------------------------------------------------------------------------------
[2023-04-05T03:00:00.654+0000] {taskinstance.py:1289} INFO - Starting attempt 1 of 1
[2023-04-05T03:00:00.654+0000] {taskinstance.py:1290} INFO - 
--------------------------------------------------------------------------------
[2023-04-05T03:00:00.668+0000] {taskinstance.py:1309} INFO - Executing <Task(PythonOperator): create_extract_data> on 2023-04-05 02:59:59.531240+00:00
[2023-04-05T03:00:00.676+0000] {standard_task_runner.py:55} INFO - Started process 451 to run task
[2023-04-05T03:00:00.679+0000] {standard_task_runner.py:82} INFO - Running: ['***', 'tasks', 'run', 'ELT', 'create_extract_data', 'manual__2023-04-05T02:59:59.531240+00:00', '--job-id', '21', '--raw', '--subdir', 'DAGS_FOLDER/elt.py', '--cfg-path', '/tmp/tmperz84x9r']
[2023-04-05T03:00:00.679+0000] {standard_task_runner.py:83} INFO - Job 21: Subtask create_extract_data
[2023-04-05T03:00:00.730+0000] {task_command.py:389} INFO - Running <TaskInstance: ELT.create_extract_data manual__2023-04-05T02:59:59.531240+00:00 [running]> on host 385ee18f1e17
[2023-04-05T03:00:00.789+0000] {taskinstance.py:1518} INFO - Exporting the following env vars:
AIRFLOW_CTX_DAG_EMAIL=200300600@ucaribe.edu.mx
AIRFLOW_CTX_DAG_OWNER=***
AIRFLOW_CTX_DAG_ID=ELT
AIRFLOW_CTX_TASK_ID=create_extract_data
AIRFLOW_CTX_EXECUTION_DATE=2023-04-05T02:59:59.531240+00:00
AIRFLOW_CTX_TRY_NUMBER=1
AIRFLOW_CTX_DAG_RUN_ID=manual__2023-04-05T02:59:59.531240+00:00
[2023-04-05T03:00:00.798+0000] {taskinstance.py:1776} ERROR - Task failed with exception
Traceback (most recent call last):
  File "/home/airflow/.local/lib/python3.7/site-packages/sqlalchemy/engine/base.py", line 3361, in _wrap_pool_connect
    return fn()
  File "/home/airflow/.local/lib/python3.7/site-packages/sqlalchemy/pool/base.py", line 327, in connect
    return _ConnectionFairy._checkout(self)
  File "/home/airflow/.local/lib/python3.7/site-packages/sqlalchemy/pool/base.py", line 894, in _checkout
    fairy = _ConnectionRecord.checkout(pool)
  File "/home/airflow/.local/lib/python3.7/site-packages/sqlalchemy/pool/base.py", line 493, in checkout
    rec = pool._do_get()
  File "/home/airflow/.local/lib/python3.7/site-packages/sqlalchemy/pool/impl.py", line 146, in _do_get
    self._dec_overflow()
  File "/home/airflow/.local/lib/python3.7/site-packages/sqlalchemy/util/langhelpers.py", line 72, in __exit__
    with_traceback=exc_tb,
  File "/home/airflow/.local/lib/python3.7/site-packages/sqlalchemy/util/compat.py", line 211, in raise_
    raise exception
  File "/home/airflow/.local/lib/python3.7/site-packages/sqlalchemy/pool/impl.py", line 143, in _do_get
    return self._create_connection()
  File "/home/airflow/.local/lib/python3.7/site-packages/sqlalchemy/pool/base.py", line 273, in _create_connection
    return _ConnectionRecord(self)
  File "/home/airflow/.local/lib/python3.7/site-packages/sqlalchemy/pool/base.py", line 388, in __init__
    self.__connect()
  File "/home/airflow/.local/lib/python3.7/site-packages/sqlalchemy/pool/base.py", line 691, in __connect
    pool.logger.debug("Error on connect(): %s", e)
  File "/home/airflow/.local/lib/python3.7/site-packages/sqlalchemy/util/langhelpers.py", line 72, in __exit__
    with_traceback=exc_tb,
  File "/home/airflow/.local/lib/python3.7/site-packages/sqlalchemy/util/compat.py", line 211, in raise_
    raise exception
  File "/home/airflow/.local/lib/python3.7/site-packages/sqlalchemy/pool/base.py", line 686, in __connect
    self.dbapi_connection = connection = pool._invoke_creator(self)
  File "/home/airflow/.local/lib/python3.7/site-packages/sqlalchemy/engine/create.py", line 574, in connect
    return dialect.connect(*cargs, **cparams)
  File "/home/airflow/.local/lib/python3.7/site-packages/sqlalchemy/engine/default.py", line 598, in connect
    return self.dbapi.connect(*cargs, **cparams)
  File "/home/airflow/.local/lib/python3.7/site-packages/psycopg2/__init__.py", line 122, in connect
    conn = _connect(dsn, connection_factory=connection_factory, **kwasync)
psycopg2.OperationalError: connection to server at "127.0.0.1", port 5434 failed: Connection refused
	Is the server running on that host and accepting TCP/IP connections?


The above exception was the direct cause of the following exception:

Traceback (most recent call last):
  File "/home/airflow/.local/lib/python3.7/site-packages/airflow/operators/python.py", line 175, in execute
    return_value = self.execute_callable()
  File "/home/airflow/.local/lib/python3.7/site-packages/airflow/operators/python.py", line 192, in execute_callable
    return self.python_callable(*self.op_args, **self.op_kwargs)
  File "/opt/airflow/dags/elt.py", line 25, in load_csv_to_postgres
    existing_tables = engine.table_names()
  File "<string>", line 2, in table_names
  File "/home/airflow/.local/lib/python3.7/site-packages/sqlalchemy/util/deprecations.py", line 468, in warned
    return fn(*args, **kwargs)
  File "/home/airflow/.local/lib/python3.7/site-packages/sqlalchemy/engine/base.py", line 3331, in table_names
    with self._optional_conn_ctx_manager(connection) as conn:
  File "/usr/local/lib/python3.7/contextlib.py", line 112, in __enter__
    return next(self.gen)
  File "/home/airflow/.local/lib/python3.7/site-packages/sqlalchemy/engine/base.py", line 3083, in _optional_conn_ctx_manager
    with self.connect() as conn:
  File "/home/airflow/.local/lib/python3.7/site-packages/sqlalchemy/engine/base.py", line 3315, in connect
    return self._connection_cls(self, close_with_result=close_with_result)
  File "/home/airflow/.local/lib/python3.7/site-packages/sqlalchemy/engine/base.py", line 96, in __init__
    else engine.raw_connection()
  File "/home/airflow/.local/lib/python3.7/site-packages/sqlalchemy/engine/base.py", line 3394, in raw_connection
    return self._wrap_pool_connect(self.pool.connect, _connection)
  File "/home/airflow/.local/lib/python3.7/site-packages/sqlalchemy/engine/base.py", line 3365, in _wrap_pool_connect
    e, dialect, self
  File "/home/airflow/.local/lib/python3.7/site-packages/sqlalchemy/engine/base.py", line 2199, in _handle_dbapi_exception_noconnection
    sqlalchemy_exception, with_traceback=exc_info[2], from_=e
  File "/home/airflow/.local/lib/python3.7/site-packages/sqlalchemy/util/compat.py", line 211, in raise_
    raise exception
  File "/home/airflow/.local/lib/python3.7/site-packages/sqlalchemy/engine/base.py", line 3361, in _wrap_pool_connect
    return fn()
  File "/home/airflow/.local/lib/python3.7/site-packages/sqlalchemy/pool/base.py", line 327, in connect
    return _ConnectionFairy._checkout(self)
  File "/home/airflow/.local/lib/python3.7/site-packages/sqlalchemy/pool/base.py", line 894, in _checkout
    fairy = _ConnectionRecord.checkout(pool)
  File "/home/airflow/.local/lib/python3.7/site-packages/sqlalchemy/pool/base.py", line 493, in checkout
    rec = pool._do_get()
  File "/home/airflow/.local/lib/python3.7/site-packages/sqlalchemy/pool/impl.py", line 146, in _do_get
    self._dec_overflow()
  File "/home/airflow/.local/lib/python3.7/site-packages/sqlalchemy/util/langhelpers.py", line 72, in __exit__
    with_traceback=exc_tb,
  File "/home/airflow/.local/lib/python3.7/site-packages/sqlalchemy/util/compat.py", line 211, in raise_
    raise exception
  File "/home/airflow/.local/lib/python3.7/site-packages/sqlalchemy/pool/impl.py", line 143, in _do_get
    return self._create_connection()
  File "/home/airflow/.local/lib/python3.7/site-packages/sqlalchemy/pool/base.py", line 273, in _create_connection
    return _ConnectionRecord(self)
  File "/home/airflow/.local/lib/python3.7/site-packages/sqlalchemy/pool/base.py", line 388, in __init__
    self.__connect()
  File "/home/airflow/.local/lib/python3.7/site-packages/sqlalchemy/pool/base.py", line 691, in __connect
    pool.logger.debug("Error on connect(): %s", e)
  File "/home/airflow/.local/lib/python3.7/site-packages/sqlalchemy/util/langhelpers.py", line 72, in __exit__
    with_traceback=exc_tb,
  File "/home/airflow/.local/lib/python3.7/site-packages/sqlalchemy/util/compat.py", line 211, in raise_
    raise exception
  File "/home/airflow/.local/lib/python3.7/site-packages/sqlalchemy/pool/base.py", line 686, in __connect
    self.dbapi_connection = connection = pool._invoke_creator(self)
  File "/home/airflow/.local/lib/python3.7/site-packages/sqlalchemy/engine/create.py", line 574, in connect
    return dialect.connect(*cargs, **cparams)
  File "/home/airflow/.local/lib/python3.7/site-packages/sqlalchemy/engine/default.py", line 598, in connect
    return self.dbapi.connect(*cargs, **cparams)
  File "/home/airflow/.local/lib/python3.7/site-packages/psycopg2/__init__.py", line 122, in connect
    conn = _connect(dsn, connection_factory=connection_factory, **kwasync)
sqlalchemy.exc.OperationalError: (psycopg2.OperationalError) connection to server at "127.0.0.1", port 5434 failed: Connection refused
	Is the server running on that host and accepting TCP/IP connections?

(Background on this error at: https://sqlalche.me/e/14/e3q8)
[2023-04-05T03:00:00.809+0000] {taskinstance.py:1332} INFO - Marking task as FAILED. dag_id=ELT, task_id=create_extract_data, execution_date=20230405T025959, start_date=20230405T030000, end_date=20230405T030000
[2023-04-05T03:00:00.819+0000] {warnings.py:110} WARNING - /home/***/.local/lib/python3.7/site-packages/***/utils/email.py:152: RemovedInAirflow3Warning: Fetching SMTP credentials from configuration variables will be deprecated in a future release. Please set credentials using a connection instead.
  send_mime_email(e_from=mail_from, e_to=recipients, mime_msg=msg, conn_id=conn_id, dryrun=dryrun)

[2023-04-05T03:00:00.820+0000] {configuration.py:664} WARNING - section/key [smtp/smtp_user] not found in config
[2023-04-05T03:00:00.820+0000] {email.py:268} INFO - Email alerting: attempt 1
[2023-04-05T03:00:00.829+0000] {configuration.py:664} WARNING - section/key [smtp/smtp_user] not found in config
[2023-04-05T03:00:00.829+0000] {email.py:268} INFO - Email alerting: attempt 1
[2023-04-05T03:00:00.830+0000] {taskinstance.py:1839} ERROR - Failed to send email to: ['200300600@ucaribe.edu.mx']
Traceback (most recent call last):
  File "/home/airflow/.local/lib/python3.7/site-packages/sqlalchemy/engine/base.py", line 3361, in _wrap_pool_connect
    return fn()
  File "/home/airflow/.local/lib/python3.7/site-packages/sqlalchemy/pool/base.py", line 327, in connect
    return _ConnectionFairy._checkout(self)
  File "/home/airflow/.local/lib/python3.7/site-packages/sqlalchemy/pool/base.py", line 894, in _checkout
    fairy = _ConnectionRecord.checkout(pool)
  File "/home/airflow/.local/lib/python3.7/site-packages/sqlalchemy/pool/base.py", line 493, in checkout
    rec = pool._do_get()
  File "/home/airflow/.local/lib/python3.7/site-packages/sqlalchemy/pool/impl.py", line 146, in _do_get
    self._dec_overflow()
  File "/home/airflow/.local/lib/python3.7/site-packages/sqlalchemy/util/langhelpers.py", line 72, in __exit__
    with_traceback=exc_tb,
  File "/home/airflow/.local/lib/python3.7/site-packages/sqlalchemy/util/compat.py", line 211, in raise_
    raise exception
  File "/home/airflow/.local/lib/python3.7/site-packages/sqlalchemy/pool/impl.py", line 143, in _do_get
    return self._create_connection()
  File "/home/airflow/.local/lib/python3.7/site-packages/sqlalchemy/pool/base.py", line 273, in _create_connection
    return _ConnectionRecord(self)
  File "/home/airflow/.local/lib/python3.7/site-packages/sqlalchemy/pool/base.py", line 388, in __init__
    self.__connect()
  File "/home/airflow/.local/lib/python3.7/site-packages/sqlalchemy/pool/base.py", line 691, in __connect
    pool.logger.debug("Error on connect(): %s", e)
  File "/home/airflow/.local/lib/python3.7/site-packages/sqlalchemy/util/langhelpers.py", line 72, in __exit__
    with_traceback=exc_tb,
  File "/home/airflow/.local/lib/python3.7/site-packages/sqlalchemy/util/compat.py", line 211, in raise_
    raise exception
  File "/home/airflow/.local/lib/python3.7/site-packages/sqlalchemy/pool/base.py", line 686, in __connect
    self.dbapi_connection = connection = pool._invoke_creator(self)
  File "/home/airflow/.local/lib/python3.7/site-packages/sqlalchemy/engine/create.py", line 574, in connect
    return dialect.connect(*cargs, **cparams)
  File "/home/airflow/.local/lib/python3.7/site-packages/sqlalchemy/engine/default.py", line 598, in connect
    return self.dbapi.connect(*cargs, **cparams)
  File "/home/airflow/.local/lib/python3.7/site-packages/psycopg2/__init__.py", line 122, in connect
    conn = _connect(dsn, connection_factory=connection_factory, **kwasync)
psycopg2.OperationalError: connection to server at "127.0.0.1", port 5434 failed: Connection refused
	Is the server running on that host and accepting TCP/IP connections?


The above exception was the direct cause of the following exception:

Traceback (most recent call last):
  File "/home/airflow/.local/lib/python3.7/site-packages/airflow/models/taskinstance.py", line 1383, in _run_raw_task
    self._execute_task_with_callbacks(context, test_mode)
  File "/home/airflow/.local/lib/python3.7/site-packages/airflow/models/taskinstance.py", line 1529, in _execute_task_with_callbacks
    result = self._execute_task(context, task_orig)
  File "/home/airflow/.local/lib/python3.7/site-packages/airflow/models/taskinstance.py", line 1589, in _execute_task
    result = execute_callable(context=context)
  File "/home/airflow/.local/lib/python3.7/site-packages/airflow/operators/python.py", line 175, in execute
    return_value = self.execute_callable()
  File "/home/airflow/.local/lib/python3.7/site-packages/airflow/operators/python.py", line 192, in execute_callable
    return self.python_callable(*self.op_args, **self.op_kwargs)
  File "/opt/airflow/dags/elt.py", line 25, in load_csv_to_postgres
    existing_tables = engine.table_names()
  File "<string>", line 2, in table_names
  File "/home/airflow/.local/lib/python3.7/site-packages/sqlalchemy/util/deprecations.py", line 468, in warned
    return fn(*args, **kwargs)
  File "/home/airflow/.local/lib/python3.7/site-packages/sqlalchemy/engine/base.py", line 3331, in table_names
    with self._optional_conn_ctx_manager(connection) as conn:
  File "/usr/local/lib/python3.7/contextlib.py", line 112, in __enter__
    return next(self.gen)
  File "/home/airflow/.local/lib/python3.7/site-packages/sqlalchemy/engine/base.py", line 3083, in _optional_conn_ctx_manager
    with self.connect() as conn:
  File "/home/airflow/.local/lib/python3.7/site-packages/sqlalchemy/engine/base.py", line 3315, in connect
    return self._connection_cls(self, close_with_result=close_with_result)
  File "/home/airflow/.local/lib/python3.7/site-packages/sqlalchemy/engine/base.py", line 96, in __init__
    else engine.raw_connection()
  File "/home/airflow/.local/lib/python3.7/site-packages/sqlalchemy/engine/base.py", line 3394, in raw_connection
    return self._wrap_pool_connect(self.pool.connect, _connection)
  File "/home/airflow/.local/lib/python3.7/site-packages/sqlalchemy/engine/base.py", line 3365, in _wrap_pool_connect
    e, dialect, self
  File "/home/airflow/.local/lib/python3.7/site-packages/sqlalchemy/engine/base.py", line 2199, in _handle_dbapi_exception_noconnection
    sqlalchemy_exception, with_traceback=exc_info[2], from_=e
  File "/home/airflow/.local/lib/python3.7/site-packages/sqlalchemy/util/compat.py", line 211, in raise_
    raise exception
  File "/home/airflow/.local/lib/python3.7/site-packages/sqlalchemy/engine/base.py", line 3361, in _wrap_pool_connect
    return fn()
  File "/home/airflow/.local/lib/python3.7/site-packages/sqlalchemy/pool/base.py", line 327, in connect
    return _ConnectionFairy._checkout(self)
  File "/home/airflow/.local/lib/python3.7/site-packages/sqlalchemy/pool/base.py", line 894, in _checkout
    fairy = _ConnectionRecord.checkout(pool)
  File "/home/airflow/.local/lib/python3.7/site-packages/sqlalchemy/pool/base.py", line 493, in checkout
    rec = pool._do_get()
  File "/home/airflow/.local/lib/python3.7/site-packages/sqlalchemy/pool/impl.py", line 146, in _do_get
    self._dec_overflow()
  File "/home/airflow/.local/lib/python3.7/site-packages/sqlalchemy/util/langhelpers.py", line 72, in __exit__
    with_traceback=exc_tb,
  File "/home/airflow/.local/lib/python3.7/site-packages/sqlalchemy/util/compat.py", line 211, in raise_
    raise exception
  File "/home/airflow/.local/lib/python3.7/site-packages/sqlalchemy/pool/impl.py", line 143, in _do_get
    return self._create_connection()
  File "/home/airflow/.local/lib/python3.7/site-packages/sqlalchemy/pool/base.py", line 273, in _create_connection
    return _ConnectionRecord(self)
  File "/home/airflow/.local/lib/python3.7/site-packages/sqlalchemy/pool/base.py", line 388, in __init__
    self.__connect()
  File "/home/airflow/.local/lib/python3.7/site-packages/sqlalchemy/pool/base.py", line 691, in __connect
    pool.logger.debug("Error on connect(): %s", e)
  File "/home/airflow/.local/lib/python3.7/site-packages/sqlalchemy/util/langhelpers.py", line 72, in __exit__
    with_traceback=exc_tb,
  File "/home/airflow/.local/lib/python3.7/site-packages/sqlalchemy/util/compat.py", line 211, in raise_
    raise exception
  File "/home/airflow/.local/lib/python3.7/site-packages/sqlalchemy/pool/base.py", line 686, in __connect
    self.dbapi_connection = connection = pool._invoke_creator(self)
  File "/home/airflow/.local/lib/python3.7/site-packages/sqlalchemy/engine/create.py", line 574, in connect
    return dialect.connect(*cargs, **cparams)
  File "/home/airflow/.local/lib/python3.7/site-packages/sqlalchemy/engine/default.py", line 598, in connect
    return self.dbapi.connect(*cargs, **cparams)
  File "/home/airflow/.local/lib/python3.7/site-packages/psycopg2/__init__.py", line 122, in connect
    conn = _connect(dsn, connection_factory=connection_factory, **kwasync)
sqlalchemy.exc.OperationalError: (psycopg2.OperationalError) connection to server at "127.0.0.1", port 5434 failed: Connection refused
	Is the server running on that host and accepting TCP/IP connections?

(Background on this error at: https://sqlalche.me/e/14/e3q8)

During handling of the above exception, another exception occurred:

Traceback (most recent call last):
  File "/home/airflow/.local/lib/python3.7/site-packages/airflow/models/taskinstance.py", line 2239, in email_alert
    send_email(task.email, subject, html_content)
  File "/home/airflow/.local/lib/python3.7/site-packages/airflow/utils/email.py", line 91, in send_email
    **kwargs,
  File "/home/airflow/.local/lib/python3.7/site-packages/airflow/utils/email.py", line 152, in send_email_smtp
    send_mime_email(e_from=mail_from, e_to=recipients, mime_msg=msg, conn_id=conn_id, dryrun=dryrun)
  File "/home/airflow/.local/lib/python3.7/site-packages/airflow/utils/email.py", line 270, in send_mime_email
    smtp_conn = _get_smtp_connection(smtp_host, smtp_port, smtp_timeout, smtp_ssl)
  File "/home/airflow/.local/lib/python3.7/site-packages/airflow/utils/email.py", line 317, in _get_smtp_connection
    else smtplib.SMTP(host=host, port=port, timeout=timeout)
  File "/usr/local/lib/python3.7/smtplib.py", line 251, in __init__
    (code, msg) = self.connect(host, port)
  File "/usr/local/lib/python3.7/smtplib.py", line 336, in connect
    self.sock = self._get_socket(host, port, self.timeout)
  File "/usr/local/lib/python3.7/smtplib.py", line 307, in _get_socket
    self.source_address)
  File "/usr/local/lib/python3.7/socket.py", line 728, in create_connection
    raise err
  File "/usr/local/lib/python3.7/socket.py", line 716, in create_connection
    sock.connect(sa)
OSError: [Errno 99] Cannot assign requested address

During handling of the above exception, another exception occurred:

Traceback (most recent call last):
  File "/home/airflow/.local/lib/python3.7/site-packages/airflow/models/taskinstance.py", line 1837, in handle_failure
    self.email_alert(error, task)
  File "/home/airflow/.local/lib/python3.7/site-packages/airflow/models/taskinstance.py", line 2241, in email_alert
    send_email(task.email, subject, html_content_err)
  File "/home/airflow/.local/lib/python3.7/site-packages/airflow/utils/email.py", line 91, in send_email
    **kwargs,
  File "/home/airflow/.local/lib/python3.7/site-packages/airflow/utils/email.py", line 152, in send_email_smtp
    send_mime_email(e_from=mail_from, e_to=recipients, mime_msg=msg, conn_id=conn_id, dryrun=dryrun)
  File "/home/airflow/.local/lib/python3.7/site-packages/airflow/utils/email.py", line 270, in send_mime_email
    smtp_conn = _get_smtp_connection(smtp_host, smtp_port, smtp_timeout, smtp_ssl)
  File "/home/airflow/.local/lib/python3.7/site-packages/airflow/utils/email.py", line 317, in _get_smtp_connection
    else smtplib.SMTP(host=host, port=port, timeout=timeout)
  File "/usr/local/lib/python3.7/smtplib.py", line 251, in __init__
    (code, msg) = self.connect(host, port)
  File "/usr/local/lib/python3.7/smtplib.py", line 336, in connect
    self.sock = self._get_socket(host, port, self.timeout)
  File "/usr/local/lib/python3.7/smtplib.py", line 307, in _get_socket
    self.source_address)
  File "/usr/local/lib/python3.7/socket.py", line 728, in create_connection
    raise err
  File "/usr/local/lib/python3.7/socket.py", line 716, in create_connection
    sock.connect(sa)
OSError: [Errno 99] Cannot assign requested address
[2023-04-05T03:00:00.844+0000] {standard_task_runner.py:105} ERROR - Failed to execute job 21 for task create_extract_data ((psycopg2.OperationalError) connection to server at "127.0.0.1", port 5434 failed: Connection refused
	Is the server running on that host and accepting TCP/IP connections?

(Background on this error at: https://sqlalche.me/e/14/e3q8); 451)
[2023-04-05T03:00:00.891+0000] {local_task_job.py:212} INFO - Task exited with return code 1
[2023-04-05T03:00:00.914+0000] {taskinstance.py:2596} INFO - 0 downstream tasks scheduled from follow-on schedule check
